<?xml version="1.0" ?>
<!-- =================================================================================== -->
<!-- |    This document was autogenerated by xacro from panda_arm.urdf.xacro           | -->
<!-- |    EDITING THIS FILE BY HAND IS NOT RECOMMENDED                                 | -->
<!-- =================================================================================== -->
<robot name="yellowarm" xmlns:xacro="http://www.ros.org/wiki/xacro">
  <link name="yellowarm_link0">
    <visual>
      <geometry>
        <mesh filename="package://yellowarm_description/meshes/visual/body1.stl"/>
      </geometry>
      <origin rpy="1.57079 0 0" xyz="0 0 0.066"/>
      <material name = "gray0">
        <color rgba = "0 1 1 1"/>
      </material>
    </visual>
    <collision>
      <geometry>
        <mesh filename="package://yellowarm_description/meshes/collision/body1.stl"/>
      </geometry>
      <origin rpy="1.57079 0 0" xyz="0 0 0.066"/>
    </collision>
    <inertial>
      <origin rpy="0 0 0" xyz="0.074 0.137 -0.042"/>
      <mass value="2.678"/>
      <inertia ixx="0.011" ixy="0.00057" ixz="-0.0031" iyy="0.026" iyz="0.000023" izz="0.030"/>
    </inertial>
  </link>
  <link name="yellowarm_link1">
    <visual>
      <geometry>
        <mesh filename="package://yellowarm_description/meshes/visual/body2.stl"/>
      </geometry>
      <origin rpy="0 0 0" xyz="0 0 -0.008"/>
      <material name = "gray1">
        <color rgba = "1 1 0 1"/>
      </material>
    </visual>
    <collision>
      <geometry>
        <mesh filename="package://yellowarm_description/meshes/collision/body2.stl"/>
      </geometry>
      <origin rpy="0 0 0" xyz="0 0 -0.008"/>
    </collision>
    <inertial>
      <origin rpy="0 0 0" xyz="-0.00046 -0.0050 0.037"/>
      <mass value="1.883"/>
      <inertia ixx="0.010" ixy="0.0000072" ixz="-0.000043" iyy="0.012" iyz="-0.00054" izz="0.013"/>
    </inertial>
  </link>
  <joint name="yellowarm_joint1" type="revolute">
    <origin rpy="0 0 -1.57079" xyz="0 0 0.078"/>
    <parent link="yellowarm_link0"/>
    <child link="yellowarm_link1"/>
    <axis xyz="0 0 1"/>
    <limit effort="22.8" lower="-4.57276" upper="1.43118" velocity="1.57079"/>
  </joint>
  <link name="yellowarm_link2">
    <visual>
      <geometry>
        <mesh filename="package://yellowarm_description/meshes/visual/body3.stl"/>
      </geometry>
      <origin rpy="0 0 0" xyz="0 0 -0.265"/>
      <material name = "gray2">
        <color rgba = "0 1 1 1"/>
      </material>
    </visual>
    <collision>
      <geometry>
        <mesh filename="package://yellowarm_description/meshes/collision/body3.stl"/>
      </geometry>
      <origin rpy="0 0 0" xyz="0 0 -0.265"/>
    </collision>
    <inertial>
      <origin rpy="0 0 0" xyz="-0.00046 -0.0050 0.037"/>
      <mass value="1.883"/>
      <inertia ixx="0.010" ixy="0.0000072" ixz="-0.000043" iyy="0.012" iyz="-0.00054" izz="0.013"/>
    </inertial>
  </link>
  <joint name="yellowarm_joint2" type="revolute">
    <origin rpy="-1.57079 0 0" xyz="0 0 0.192"/>
    <parent link="yellowarm_link1"/>
    <child link="yellowarm_link2"/>
    <axis xyz="1 0 0"/>
    <limit effort="29.6" lower="-0.61087" upper="2.530721" velocity="1.57079"/>
  </joint>
  <link name="yellowarm_link3">
    <visual>
      <geometry>
        <mesh filename="package://yellowarm_description/meshes/visual/body4.stl"/>
      </geometry>
      <origin rpy="0 0 0" xyz="0 0 -0.008"/>
      <material name = "gray3">
        <color rgba = "1 1 0 1"/>
      </material>
    </visual>
    <collision>
      <geometry>
        <mesh filename="package://yellowarm_description/meshes/collision/body4.stl"/>
      </geometry>
      <origin rpy="0 0 0" xyz="0 0 -0.008"/>
    </collision>
    <inertial>
      <origin rpy="0 0 0" xyz="-0.00046 -0.0050 0.037"/>
      <mass value="1.883"/>
      <inertia ixx="0.010" ixy="0.0000072" ixz="-0.000043" iyy="0.012" iyz="-0.00054" izz="0.013"/>
    </inertial>
  </link>
  <joint name="yellowarm_joint3" type="revolute">
    <origin rpy="0 0 0" xyz="0 0 0.063"/>
    <parent link="yellowarm_link2"/>
    <child link="yellowarm_link3"/>
    <axis xyz="0 0 1"/>
    <limit effort="29.6" lower="-3.00197" upper="3.00197" velocity="1.57079"/>
  </joint>
  <link name="yellowarm_link4">
    <visual>
      <geometry>
        <mesh filename="package://yellowarm_description/meshes/visual/body5.stl"/>
      </geometry>
      <origin rpy="0 0 0" xyz="0 0 -0.265"/>
      <material name = "gray4">
        <color rgba = "0 1 1 1"/>
      </material>
    </visual>
    <collision>
      <geometry>
        <mesh filename="package://yellowarm_description/meshes/collision/body5.stl"/>
      </geometry>
      <origin rpy="0 0 0" xyz="0 0 -0.265"/>
    </collision>
    <inertial>
      <origin rpy="0 0 0" xyz="-0.00046 -0.0050 0.037"/>
      <mass value="1.883"/>
      <inertia ixx="0.010" ixy="0.0000072" ixz="-0.000043" iyy="0.012" iyz="-0.00054" izz="0.013"/>
    </inertial>
  </link>
  <joint name="yellowarm_joint4" type="revolute">
    <origin rpy="0 0 0" xyz="0 0 0.257"/>
    <parent link="yellowarm_link3"/>
    <child link="yellowarm_link4"/>
    <axis xyz="1 0 0"/>
    <limit effort="29.6" lower="-2.35619" upper="1.22173" velocity="1.57079"/>
  </joint>
  <link name="yellowarm_link5">
    <visual>
      <geometry>
        <mesh filename="package://yellowarm_description/meshes/visual/body6.stl"/>
      </geometry>
      <origin rpy="0 0 0" xyz="0 0 -0.008"/>
      <material name = "gray5">
        <color rgba = "1 1 0 1"/>
      </material>
    </visual>
    <collision>
      <geometry>
        <mesh filename="package://yellowarm_description/meshes/collision/body6.stl"/>
      </geometry>
      <origin rpy="0 0 0" xyz="0 0 -0.008"/>
    </collision>
    <inertial>
      <origin rpy="0 0 0" xyz="-0.00046 -0.0050 0.037"/>
      <mass value="1.883"/>
      <inertia ixx="0.010" ixy="0.0000072" ixz="-0.000043" iyy="0.012" iyz="-0.00054" izz="0.013"/>
    </inertial>
  </link>
  <joint name="yellowarm_joint5" type="revolute">
    <origin rpy="0 0 0" xyz="0 0 0.063"/>
    <parent link="yellowarm_link4"/>
    <child link="yellowarm_link5"/>
    <axis xyz="0 0 1"/>
    <limit effort="29.6" lower="-3.00197" upper="3.00197" velocity="1.57079"/>
  </joint>
  <link name="yellowarm_link6">
    <visual>
      <geometry>
        <mesh filename="package://yellowarm_description/meshes/visual/body7.stl"/>
      </geometry>
      <origin rpy="0 0 0" xyz="0 0 -0.225"/>
      <material name = "gray6">
        <color rgba = "0 1 1 1"/>
      </material>
    </visual>
    <collision>
      <geometry>
        <mesh filename="package://yellowarm_description/meshes/collision/body7.stl"/>
      </geometry>
      <origin rpy="0 0 0" xyz="0 0 -0.225"/>
    </collision>
    <inertial>
      <origin rpy="0 0 0" xyz="-0.00046 -0.0050 0.037"/>
      <mass value="1.883"/>
      <inertia ixx="0.010" ixy="0.0000072" ixz="-0.000043" iyy="0.012" iyz="-0.00054" izz="0.013"/>
    </inertial>
  </link>
  <joint name="yellowarm_joint6" type="revolute">
    <origin rpy="0 0 0" xyz="0 0 0.217"/>
    <parent link="yellowarm_link5"/>
    <child link="yellowarm_link6"/>
    <axis xyz="1 0 0"/>
    <limit effort="29.6" lower="-1.5708" upper="1.5708" velocity="1.57079"/>
  </joint>
  <link name="yellowarm_link7">
    <visual>
      <geometry>
        <mesh filename="package://yellowarm_description/meshes/visual/body8.stl"/>
      </geometry>
      <origin rpy="0 0 0" xyz="-0.00975 0 0.051"/>
      <material name = "gray7">
        <color rgba = "0 1 0 1"/>
      </material>
    </visual>
    <collision>
      <geometry>
        <mesh filename="package://yellowarm_description/meshes/collision/body8.stl"/>
      </geometry>
      <origin rpy="0 0 0" xyz="-0.00975 0 0.051"/>
    </collision>
    <inertial>
      <origin rpy="0 0 0" xyz="-0.00046 -0.0050 0.037"/>
      <mass value="1.883"/>
      <inertia ixx="0.010" ixy="0.0000072" ixz="-0.000043" iyy="0.012" iyz="-0.00054" izz="0.013"/>
    </inertial>
  </link>
  <joint name="yellowarm_joint7" type="revolute">
    <origin rpy="0 0 -1.57079" xyz="0 0 0.048"/>
    <parent link="yellowarm_link6"/>
    <child link="yellowarm_link7"/>
    <axis xyz="0 0 1"/>
    <limit effort="29.6" lower="-3.49066" upper="2.40855" velocity="1.57079"/>
  </joint>
  <link name="yellowarm_link8">
    <visual>
      <geometry>
        <mesh filename="package://yellowarm_description/meshes/visual/body9.stl"/>
      </geometry>
      <origin rpy="0 0 0" xyz="-0.00975 0 0.051"/>
      <material name = "gray8">
        <color rgba = "1 1 0 1"/>
      </material>
    </visual>
    <collision>
      <geometry>
        <mesh filename="package://yellowarm_description/meshes/collision/body9.stl"/>
      </geometry>
      <origin rpy="0 0 0" xyz="-0.00975 0 0.051"/>
    </collision>
    <inertial>
      <origin rpy="0 0 0" xyz="-0.00046 -0.0050 0.037"/>
      <mass value="1.883"/>
      <inertia ixx="0.010" ixy="0.0000072" ixz="-0.000043" iyy="0.012" iyz="-0.00054" izz="0.013"/>
    </inertial>
  </link>
  <joint name="yellowarm_joint8" type="prismatic">
    <origin rpy="0 0 0" xyz="0 0 0"/>
    <parent link="yellowarm_link7"/>
    <child link="yellowarm_link8"/>
    <axis xyz="0 1 0"/>
    <limit effort="29.6" lower="-0.022" upper="0.015" velocity="1.57079"/>
  </joint>
  <link name="yellowarm_link9">
    <visual>
      <geometry>
        <mesh filename="package://yellowarm_description/meshes/visual/body10.stl"/>
      </geometry>
      <origin rpy="0 0 0" xyz="-0.00975 0 0.051"/>
      <material name = "gray9">
        <color rgba = "1 1 0 1"/>
      </material>
    </visual>
    <collision>
      <geometry>
        <mesh filename="package://yellowarm_description/meshes/collision/body10.stl"/>
      </geometry>
      <origin rpy="0 0 0" xyz="-0.00975 0 0.051"/>
    </collision>
    <inertial>
      <origin rpy="0 0 0" xyz="-0.00046 -0.0050 0.037"/>
      <mass value="1.883"/>
      <inertia ixx="0.010" ixy="0.0000072" ixz="-0.000043" iyy="0.012" iyz="-0.00054" izz="0.013"/>
    </inertial>
  </link>
  <joint name="yellowarm_joint9" type="prismatic">
    <origin rpy="0 0 0" xyz="0 0 0"/>
    <parent link="yellowarm_link7"/>
    <child link="yellowarm_link9"/>
    <axis xyz="0 -1 0"/>
    <limit effort="29.6" lower="-0.022" upper="0.015" velocity="1.57079"/>
    <mimic joint="yellowarm_joint8" multiplier="1" offset="0" />
  </joint>
</robot>
